ERROR 2022-09-19 21:34:08,575 241 log.py log 31826 123145480716288 Internal Server Error: /api/v1/auth/register/
Traceback (most recent call last):
  File "/Users/owner/Desktop/redal/venv/lib/python3.10/site-packages/django/core/handlers/exception.py", line 55, in inner
    response = get_response(request)
  File "/Users/owner/Desktop/redal/venv/lib/python3.10/site-packages/django/core/handlers/base.py", line 197, in _get_response
    response = wrapped_callback(request, *callback_args, **callback_kwargs)
  File "/Users/owner/Desktop/redal/venv/lib/python3.10/site-packages/django/views/decorators/csrf.py", line 54, in wrapped_view
    return view_func(*args, **kwargs)
  File "/Users/owner/Desktop/redal/venv/lib/python3.10/site-packages/django/views/generic/base.py", line 103, in view
    return self.dispatch(request, *args, **kwargs)
  File "/Users/owner/Desktop/redal/venv/lib/python3.10/site-packages/rest_framework/views.py", line 509, in dispatch
    response = self.handle_exception(exc)
  File "/Users/owner/Desktop/redal/venv/lib/python3.10/site-packages/rest_framework/views.py", line 469, in handle_exception
    self.raise_uncaught_exception(exc)
  File "/Users/owner/Desktop/redal/venv/lib/python3.10/site-packages/rest_framework/views.py", line 480, in raise_uncaught_exception
    raise exc
  File "/Users/owner/Desktop/redal/venv/lib/python3.10/site-packages/rest_framework/views.py", line 506, in dispatch
    response = handler(request, *args, **kwargs)
  File "/Users/owner/Desktop/redal/authentication/views.py", line 25, in post
    serializer.is_valid(raise_exception=True)
  File "/Users/owner/Desktop/redal/venv/lib/python3.10/site-packages/rest_framework/serializers.py", line 227, in is_valid
    self._validated_data = self.run_validation(self.initial_data)
  File "/Users/owner/Desktop/redal/venv/lib/python3.10/site-packages/rest_framework/serializers.py", line 426, in run_validation
    value = self.to_internal_value(data)
  File "/Users/owner/Desktop/redal/venv/lib/python3.10/site-packages/rest_framework/serializers.py", line 479, in to_internal_value
    for field in fields:
  File "/Users/owner/Desktop/redal/venv/lib/python3.10/site-packages/rest_framework/serializers.py", line 362, in _writable_fields
    for field in self.fields.values():
  File "/Users/owner/Desktop/redal/venv/lib/python3.10/site-packages/django/utils/functional.py", line 57, in __get__
    res = instance.__dict__[self.name] = self.func(instance)
  File "/Users/owner/Desktop/redal/venv/lib/python3.10/site-packages/rest_framework/serializers.py", line 356, in fields
    for key, value in self.get_fields().items():
  File "/Users/owner/Desktop/redal/venv/lib/python3.10/site-packages/rest_framework/serializers.py", line 1052, in get_fields
    field_names = self.get_field_names(declared_fields, info)
  File "/Users/owner/Desktop/redal/venv/lib/python3.10/site-packages/rest_framework/serializers.py", line 1148, in get_field_names
    assert field_name in fields, (
AssertionError: The field 'confirm_password' was declared on serializer RegisterSerializer, but has not been included in the 'fields' option.
ERROR 2022-09-19 21:34:08,577 187 basehttp.py basehttp 31826 123145480716288 "POST /api/v1/auth/register/ HTTP/1.1" 500 136045
ERROR 2022-09-19 21:34:39,046 241 log.py log 31916 123145402073088 Internal Server Error: /api/v1/auth/register/
Traceback (most recent call last):
  File "/Users/owner/Desktop/redal/venv/lib/python3.10/site-packages/django/core/handlers/exception.py", line 55, in inner
    response = get_response(request)
  File "/Users/owner/Desktop/redal/venv/lib/python3.10/site-packages/django/core/handlers/base.py", line 197, in _get_response
    response = wrapped_callback(request, *callback_args, **callback_kwargs)
  File "/Users/owner/Desktop/redal/venv/lib/python3.10/site-packages/django/views/decorators/csrf.py", line 54, in wrapped_view
    return view_func(*args, **kwargs)
  File "/Users/owner/Desktop/redal/venv/lib/python3.10/site-packages/django/views/generic/base.py", line 103, in view
    return self.dispatch(request, *args, **kwargs)
  File "/Users/owner/Desktop/redal/venv/lib/python3.10/site-packages/rest_framework/views.py", line 509, in dispatch
    response = self.handle_exception(exc)
  File "/Users/owner/Desktop/redal/venv/lib/python3.10/site-packages/rest_framework/views.py", line 469, in handle_exception
    self.raise_uncaught_exception(exc)
  File "/Users/owner/Desktop/redal/venv/lib/python3.10/site-packages/rest_framework/views.py", line 480, in raise_uncaught_exception
    raise exc
  File "/Users/owner/Desktop/redal/venv/lib/python3.10/site-packages/rest_framework/views.py", line 506, in dispatch
    response = handler(request, *args, **kwargs)
  File "/Users/owner/Desktop/redal/authentication/views.py", line 25, in post
    serializer.is_valid(raise_exception=True)
  File "/Users/owner/Desktop/redal/venv/lib/python3.10/site-packages/rest_framework/serializers.py", line 227, in is_valid
    self._validated_data = self.run_validation(self.initial_data)
  File "/Users/owner/Desktop/redal/venv/lib/python3.10/site-packages/rest_framework/serializers.py", line 426, in run_validation
    value = self.to_internal_value(data)
  File "/Users/owner/Desktop/redal/venv/lib/python3.10/site-packages/rest_framework/serializers.py", line 479, in to_internal_value
    for field in fields:
  File "/Users/owner/Desktop/redal/venv/lib/python3.10/site-packages/rest_framework/serializers.py", line 362, in _writable_fields
    for field in self.fields.values():
  File "/Users/owner/Desktop/redal/venv/lib/python3.10/site-packages/django/utils/functional.py", line 57, in __get__
    res = instance.__dict__[self.name] = self.func(instance)
  File "/Users/owner/Desktop/redal/venv/lib/python3.10/site-packages/rest_framework/serializers.py", line 356, in fields
    for key, value in self.get_fields().items():
  File "/Users/owner/Desktop/redal/venv/lib/python3.10/site-packages/rest_framework/serializers.py", line 1076, in get_fields
    field_class, field_kwargs = self.build_field(
  File "/Users/owner/Desktop/redal/venv/lib/python3.10/site-packages/rest_framework/serializers.py", line 1222, in build_field
    return self.build_unknown_field(field_name, model_class)
  File "/Users/owner/Desktop/redal/venv/lib/python3.10/site-packages/rest_framework/serializers.py", line 1340, in build_unknown_field
    raise ImproperlyConfigured(
django.core.exceptions.ImproperlyConfigured: Field name `password, first_name` is not valid for model `CustomUser`.
ERROR 2022-09-19 21:34:39,048 187 basehttp.py basehttp 31916 123145402073088 "POST /api/v1/auth/register/ HTTP/1.1" 500 139265
ERROR 2022-09-19 21:42:49,720 241 log.py log 32209 123145546084352 Internal Server Error: /api/v1/auth/register/
Traceback (most recent call last):
  File "/Users/owner/Desktop/redal/venv/lib/python3.10/site-packages/django/core/handlers/exception.py", line 55, in inner
    response = get_response(request)
  File "/Users/owner/Desktop/redal/venv/lib/python3.10/site-packages/django/core/handlers/base.py", line 197, in _get_response
    response = wrapped_callback(request, *callback_args, **callback_kwargs)
  File "/Users/owner/Desktop/redal/venv/lib/python3.10/site-packages/django/views/decorators/csrf.py", line 54, in wrapped_view
    return view_func(*args, **kwargs)
  File "/Users/owner/Desktop/redal/venv/lib/python3.10/site-packages/django/views/generic/base.py", line 103, in view
    return self.dispatch(request, *args, **kwargs)
  File "/Users/owner/Desktop/redal/venv/lib/python3.10/site-packages/rest_framework/views.py", line 509, in dispatch
    response = self.handle_exception(exc)
  File "/Users/owner/Desktop/redal/venv/lib/python3.10/site-packages/rest_framework/views.py", line 469, in handle_exception
    self.raise_uncaught_exception(exc)
  File "/Users/owner/Desktop/redal/venv/lib/python3.10/site-packages/rest_framework/views.py", line 480, in raise_uncaught_exception
    raise exc
  File "/Users/owner/Desktop/redal/venv/lib/python3.10/site-packages/rest_framework/views.py", line 506, in dispatch
    response = handler(request, *args, **kwargs)
  File "/Users/owner/Desktop/redal/authentication/views.py", line 25, in post
    serializer.is_valid(raise_exception=True)
  File "/Users/owner/Desktop/redal/venv/lib/python3.10/site-packages/rest_framework/serializers.py", line 227, in is_valid
    self._validated_data = self.run_validation(self.initial_data)
  File "/Users/owner/Desktop/redal/venv/lib/python3.10/site-packages/rest_framework/serializers.py", line 426, in run_validation
    value = self.to_internal_value(data)
  File "/Users/owner/Desktop/redal/venv/lib/python3.10/site-packages/rest_framework/serializers.py", line 479, in to_internal_value
    for field in fields:
  File "/Users/owner/Desktop/redal/venv/lib/python3.10/site-packages/rest_framework/serializers.py", line 362, in _writable_fields
    for field in self.fields.values():
  File "/Users/owner/Desktop/redal/venv/lib/python3.10/site-packages/django/utils/functional.py", line 57, in __get__
    res = instance.__dict__[self.name] = self.func(instance)
  File "/Users/owner/Desktop/redal/venv/lib/python3.10/site-packages/rest_framework/serializers.py", line 356, in fields
    for key, value in self.get_fields().items():
  File "/Users/owner/Desktop/redal/venv/lib/python3.10/site-packages/rest_framework/serializers.py", line 1076, in get_fields
    field_class, field_kwargs = self.build_field(
  File "/Users/owner/Desktop/redal/venv/lib/python3.10/site-packages/rest_framework/serializers.py", line 1222, in build_field
    return self.build_unknown_field(field_name, model_class)
  File "/Users/owner/Desktop/redal/venv/lib/python3.10/site-packages/rest_framework/serializers.py", line 1340, in build_unknown_field
    raise ImproperlyConfigured(
django.core.exceptions.ImproperlyConfigured: Field name `password, first_name` is not valid for model `CustomUser`.
ERROR 2022-09-19 21:42:49,722 187 basehttp.py basehttp 32209 123145546084352 "POST /api/v1/auth/register/ HTTP/1.1" 500 139265
ERROR 2022-09-19 21:43:34,473 241 log.py log 32227 123145565192192 Internal Server Error: /api/v1/auth/register/
Traceback (most recent call last):
  File "/Users/owner/Desktop/redal/venv/lib/python3.10/site-packages/django/core/handlers/exception.py", line 55, in inner
    response = get_response(request)
  File "/Users/owner/Desktop/redal/venv/lib/python3.10/site-packages/django/core/handlers/base.py", line 197, in _get_response
    response = wrapped_callback(request, *callback_args, **callback_kwargs)
  File "/Users/owner/Desktop/redal/venv/lib/python3.10/site-packages/django/views/decorators/csrf.py", line 54, in wrapped_view
    return view_func(*args, **kwargs)
  File "/Users/owner/Desktop/redal/venv/lib/python3.10/site-packages/django/views/generic/base.py", line 103, in view
    return self.dispatch(request, *args, **kwargs)
  File "/Users/owner/Desktop/redal/venv/lib/python3.10/site-packages/rest_framework/views.py", line 509, in dispatch
    response = self.handle_exception(exc)
  File "/Users/owner/Desktop/redal/venv/lib/python3.10/site-packages/rest_framework/views.py", line 469, in handle_exception
    self.raise_uncaught_exception(exc)
  File "/Users/owner/Desktop/redal/venv/lib/python3.10/site-packages/rest_framework/views.py", line 480, in raise_uncaught_exception
    raise exc
  File "/Users/owner/Desktop/redal/venv/lib/python3.10/site-packages/rest_framework/views.py", line 506, in dispatch
    response = handler(request, *args, **kwargs)
  File "/Users/owner/Desktop/redal/authentication/views.py", line 25, in post
    serializer.is_valid(raise_exception=True)
  File "/Users/owner/Desktop/redal/venv/lib/python3.10/site-packages/rest_framework/serializers.py", line 227, in is_valid
    self._validated_data = self.run_validation(self.initial_data)
  File "/Users/owner/Desktop/redal/venv/lib/python3.10/site-packages/rest_framework/serializers.py", line 426, in run_validation
    value = self.to_internal_value(data)
  File "/Users/owner/Desktop/redal/venv/lib/python3.10/site-packages/rest_framework/serializers.py", line 479, in to_internal_value
    for field in fields:
  File "/Users/owner/Desktop/redal/venv/lib/python3.10/site-packages/rest_framework/serializers.py", line 362, in _writable_fields
    for field in self.fields.values():
  File "/Users/owner/Desktop/redal/venv/lib/python3.10/site-packages/django/utils/functional.py", line 57, in __get__
    res = instance.__dict__[self.name] = self.func(instance)
  File "/Users/owner/Desktop/redal/venv/lib/python3.10/site-packages/rest_framework/serializers.py", line 356, in fields
    for key, value in self.get_fields().items():
  File "/Users/owner/Desktop/redal/venv/lib/python3.10/site-packages/rest_framework/serializers.py", line 1076, in get_fields
    field_class, field_kwargs = self.build_field(
  File "/Users/owner/Desktop/redal/venv/lib/python3.10/site-packages/rest_framework/serializers.py", line 1222, in build_field
    return self.build_unknown_field(field_name, model_class)
  File "/Users/owner/Desktop/redal/venv/lib/python3.10/site-packages/rest_framework/serializers.py", line 1340, in build_unknown_field
    raise ImproperlyConfigured(
django.core.exceptions.ImproperlyConfigured: Field name `password, first_name` is not valid for model `CustomUser`.
ERROR 2022-09-19 21:43:34,477 187 basehttp.py basehttp 32227 123145565192192 "POST /api/v1/auth/register/ HTTP/1.1" 500 139265
ERROR 2022-09-19 21:58:07,366 241 log.py log 32618 123145561399296 Internal Server Error: /api/v1/auth/register/
Traceback (most recent call last):
  File "/Users/owner/Desktop/redal/venv/lib/python3.10/site-packages/django/core/handlers/exception.py", line 55, in inner
    response = get_response(request)
  File "/Users/owner/Desktop/redal/venv/lib/python3.10/site-packages/django/core/handlers/base.py", line 220, in _get_response
    response = response.render()
  File "/Users/owner/Desktop/redal/venv/lib/python3.10/site-packages/django/template/response.py", line 114, in render
    self.content = self.rendered_content
  File "/Users/owner/Desktop/redal/venv/lib/python3.10/site-packages/rest_framework/response.py", line 70, in rendered_content
    ret = renderer.render(self.data, accepted_media_type, context)
  File "/Users/owner/Desktop/redal/venv/lib/python3.10/site-packages/rest_framework/renderers.py", line 100, in render
    ret = json.dumps(
  File "/Users/owner/Desktop/redal/venv/lib/python3.10/site-packages/rest_framework/utils/json.py", line 25, in dumps
    return json.dumps(*args, **kwargs)
  File "/Library/Frameworks/Python.framework/Versions/3.10/lib/python3.10/json/__init__.py", line 238, in dumps
    **kw).encode(obj)
  File "/Library/Frameworks/Python.framework/Versions/3.10/lib/python3.10/json/encoder.py", line 199, in encode
    chunks = self.iterencode(o, _one_shot=True)
  File "/Library/Frameworks/Python.framework/Versions/3.10/lib/python3.10/json/encoder.py", line 257, in iterencode
    return _iterencode(o, 0)
  File "/Users/owner/Desktop/redal/venv/lib/python3.10/site-packages/rest_framework/utils/encoders.py", line 67, in default
    return super().default(obj)
  File "/Library/Frameworks/Python.framework/Versions/3.10/lib/python3.10/json/encoder.py", line 179, in default
    raise TypeError(f'Object of type {o.__class__.__name__} '
TypeError: Object of type ValidationError is not JSON serializable
ERROR 2022-09-19 21:58:07,499 187 basehttp.py basehttp 32618 123145561399296 "POST /api/v1/auth/register/ HTTP/1.1" 500 101589
ERROR 2022-09-19 22:35:53,855 241 log.py log 33583 123145500471296 Internal Server Error: /api/v1/auth/register/
Traceback (most recent call last):
  File "/Users/owner/Desktop/redal/venv/lib/python3.10/site-packages/django/core/handlers/exception.py", line 55, in inner
    response = get_response(request)
  File "/Users/owner/Desktop/redal/venv/lib/python3.10/site-packages/django/core/handlers/base.py", line 197, in _get_response
    response = wrapped_callback(request, *callback_args, **callback_kwargs)
  File "/Users/owner/Desktop/redal/venv/lib/python3.10/site-packages/django/views/decorators/csrf.py", line 54, in wrapped_view
    return view_func(*args, **kwargs)
  File "/Users/owner/Desktop/redal/venv/lib/python3.10/site-packages/django/views/generic/base.py", line 103, in view
    return self.dispatch(request, *args, **kwargs)
  File "/Users/owner/Desktop/redal/venv/lib/python3.10/site-packages/rest_framework/views.py", line 509, in dispatch
    response = self.handle_exception(exc)
  File "/Users/owner/Desktop/redal/venv/lib/python3.10/site-packages/rest_framework/views.py", line 469, in handle_exception
    self.raise_uncaught_exception(exc)
  File "/Users/owner/Desktop/redal/venv/lib/python3.10/site-packages/rest_framework/views.py", line 480, in raise_uncaught_exception
    raise exc
  File "/Users/owner/Desktop/redal/venv/lib/python3.10/site-packages/rest_framework/views.py", line 506, in dispatch
    response = handler(request, *args, **kwargs)
  File "/Users/owner/Desktop/redal/authentication/views.py", line 25, in post
    serializer.is_valid(raise_exception=True)
  File "/Users/owner/Desktop/redal/venv/lib/python3.10/site-packages/rest_framework/serializers.py", line 227, in is_valid
    self._validated_data = self.run_validation(self.initial_data)
  File "/Users/owner/Desktop/redal/venv/lib/python3.10/site-packages/rest_framework/serializers.py", line 429, in run_validation
    value = self.validate(value)
  File "/Users/owner/Desktop/redal/authentication/serializers.py", line 48, in validate
    print(data['password'], data['confirm_password'])
KeyError: 'password'
ERROR 2022-09-19 22:35:53,857 187 basehttp.py basehttp 33583 123145500471296 "POST /api/v1/auth/register/ HTTP/1.1" 500 105559
ERROR 2022-09-19 23:21:32,339 241 log.py log 35026 123145534496768 Internal Server Error: /api/v1/auth/register/
Traceback (most recent call last):
  File "/Users/owner/Desktop/redal/venv/lib/python3.10/site-packages/rest_framework/serializers.py", line 962, in create
    instance = ModelClass._default_manager.create(**validated_data)
  File "/Users/owner/Desktop/redal/account/models.py", line 30, in create
    user = self.model(email=email, password=password, **extra_fields)
  File "/Users/owner/Desktop/redal/venv/lib/python3.10/site-packages/django/db/models/base.py", line 585, in __init__
    raise TypeError(
TypeError: CustomUser() got unexpected keyword arguments: 'confirm_password'

During handling of the above exception, another exception occurred:

Traceback (most recent call last):
  File "/Users/owner/Desktop/redal/venv/lib/python3.10/site-packages/django/core/handlers/exception.py", line 55, in inner
    response = get_response(request)
  File "/Users/owner/Desktop/redal/venv/lib/python3.10/site-packages/django/core/handlers/base.py", line 197, in _get_response
    response = wrapped_callback(request, *callback_args, **callback_kwargs)
  File "/Users/owner/Desktop/redal/venv/lib/python3.10/site-packages/django/views/decorators/csrf.py", line 54, in wrapped_view
    return view_func(*args, **kwargs)
  File "/Users/owner/Desktop/redal/venv/lib/python3.10/site-packages/django/views/generic/base.py", line 103, in view
    return self.dispatch(request, *args, **kwargs)
  File "/Users/owner/Desktop/redal/venv/lib/python3.10/site-packages/rest_framework/views.py", line 509, in dispatch
    response = self.handle_exception(exc)
  File "/Users/owner/Desktop/redal/venv/lib/python3.10/site-packages/rest_framework/views.py", line 469, in handle_exception
    self.raise_uncaught_exception(exc)
  File "/Users/owner/Desktop/redal/venv/lib/python3.10/site-packages/rest_framework/views.py", line 480, in raise_uncaught_exception
    raise exc
  File "/Users/owner/Desktop/redal/venv/lib/python3.10/site-packages/rest_framework/views.py", line 506, in dispatch
    response = handler(request, *args, **kwargs)
  File "/Users/owner/Desktop/redal/authentication/views.py", line 27, in post
    serializer.create(serializer.validated_data)
  File "/Users/owner/Desktop/redal/venv/lib/python3.10/site-packages/rest_framework/serializers.py", line 981, in create
    raise TypeError(msg)
TypeError: Got a `TypeError` when calling `CustomUser.objects.create()`. This may be because you have a writable field on the serializer class that is not a valid argument to `CustomUser.objects.create()`. You may need to make the field read-only, or override the RegisterSerializer.create() method to handle this correctly.
Original exception was:
 Traceback (most recent call last):
  File "/Users/owner/Desktop/redal/venv/lib/python3.10/site-packages/rest_framework/serializers.py", line 962, in create
    instance = ModelClass._default_manager.create(**validated_data)
  File "/Users/owner/Desktop/redal/account/models.py", line 30, in create
    user = self.model(email=email, password=password, **extra_fields)
  File "/Users/owner/Desktop/redal/venv/lib/python3.10/site-packages/django/db/models/base.py", line 585, in __init__
    raise TypeError(
TypeError: CustomUser() got unexpected keyword arguments: 'confirm_password'

ERROR 2022-09-19 23:21:32,374 187 basehttp.py basehttp 35026 123145534496768 "POST /api/v1/auth/register/ HTTP/1.1" 500 134687
ERROR 2022-09-19 23:23:45,916 241 log.py log 35149 123145475653632 Internal Server Error: /api/v1/auth/register/
Traceback (most recent call last):
  File "/Users/owner/Desktop/redal/venv/lib/python3.10/site-packages/django/core/handlers/exception.py", line 55, in inner
    response = get_response(request)
  File "/Users/owner/Desktop/redal/venv/lib/python3.10/site-packages/django/core/handlers/base.py", line 197, in _get_response
    response = wrapped_callback(request, *callback_args, **callback_kwargs)
  File "/Users/owner/Desktop/redal/venv/lib/python3.10/site-packages/django/views/decorators/csrf.py", line 54, in wrapped_view
    return view_func(*args, **kwargs)
  File "/Users/owner/Desktop/redal/venv/lib/python3.10/site-packages/django/views/generic/base.py", line 103, in view
    return self.dispatch(request, *args, **kwargs)
  File "/Users/owner/Desktop/redal/venv/lib/python3.10/site-packages/rest_framework/views.py", line 509, in dispatch
    response = self.handle_exception(exc)
  File "/Users/owner/Desktop/redal/venv/lib/python3.10/site-packages/rest_framework/views.py", line 469, in handle_exception
    self.raise_uncaught_exception(exc)
  File "/Users/owner/Desktop/redal/venv/lib/python3.10/site-packages/rest_framework/views.py", line 480, in raise_uncaught_exception
    raise exc
  File "/Users/owner/Desktop/redal/venv/lib/python3.10/site-packages/rest_framework/views.py", line 506, in dispatch
    response = handler(request, *args, **kwargs)
  File "/Users/owner/Desktop/redal/authentication/views.py", line 27, in post
    CustomUser.objects.create(serializer.validated_data['email'],
TypeError: CustomUserManager.create() got multiple values for argument 'password'
ERROR 2022-09-19 23:23:45,918 187 basehttp.py basehttp 35149 123145475653632 "POST /api/v1/auth/register/ HTTP/1.1" 500 92128
ERROR 2022-09-19 23:24:25,066 241 log.py log 35193 123145412972544 Internal Server Error: /api/v1/auth/register/
Traceback (most recent call last):
  File "/Users/owner/Desktop/redal/venv/lib/python3.10/site-packages/django/core/handlers/exception.py", line 55, in inner
    response = get_response(request)
  File "/Users/owner/Desktop/redal/venv/lib/python3.10/site-packages/django/core/handlers/base.py", line 197, in _get_response
    response = wrapped_callback(request, *callback_args, **callback_kwargs)
  File "/Users/owner/Desktop/redal/venv/lib/python3.10/site-packages/django/views/decorators/csrf.py", line 54, in wrapped_view
    return view_func(*args, **kwargs)
  File "/Users/owner/Desktop/redal/venv/lib/python3.10/site-packages/django/views/generic/base.py", line 103, in view
    return self.dispatch(request, *args, **kwargs)
  File "/Users/owner/Desktop/redal/venv/lib/python3.10/site-packages/rest_framework/views.py", line 509, in dispatch
    response = self.handle_exception(exc)
  File "/Users/owner/Desktop/redal/venv/lib/python3.10/site-packages/rest_framework/views.py", line 469, in handle_exception
    self.raise_uncaught_exception(exc)
  File "/Users/owner/Desktop/redal/venv/lib/python3.10/site-packages/rest_framework/views.py", line 480, in raise_uncaught_exception
    raise exc
  File "/Users/owner/Desktop/redal/venv/lib/python3.10/site-packages/rest_framework/views.py", line 506, in dispatch
    response = handler(request, *args, **kwargs)
  File "/Users/owner/Desktop/redal/authentication/views.py", line 27, in post
    CustomUser.objects.create(serializer.validated_data['email'],
TypeError: CustomUserManager.create() got multiple values for argument 'password'
ERROR 2022-09-19 23:24:25,068 187 basehttp.py basehttp 35193 123145412972544 "POST /api/v1/auth/register/ HTTP/1.1" 500 92128
ERROR 2022-09-19 23:28:02,356 241 log.py log 35362 123145342099456 Internal Server Error: /api/v1/auth/register/
Traceback (most recent call last):
  File "/Users/owner/Desktop/redal/venv/lib/python3.10/site-packages/django/core/handlers/exception.py", line 55, in inner
    response = get_response(request)
  File "/Users/owner/Desktop/redal/venv/lib/python3.10/site-packages/django/core/handlers/base.py", line 197, in _get_response
    response = wrapped_callback(request, *callback_args, **callback_kwargs)
  File "/Users/owner/Desktop/redal/venv/lib/python3.10/site-packages/django/views/decorators/csrf.py", line 54, in wrapped_view
    return view_func(*args, **kwargs)
  File "/Users/owner/Desktop/redal/venv/lib/python3.10/site-packages/django/views/generic/base.py", line 103, in view
    return self.dispatch(request, *args, **kwargs)
  File "/Users/owner/Desktop/redal/venv/lib/python3.10/site-packages/rest_framework/views.py", line 509, in dispatch
    response = self.handle_exception(exc)
  File "/Users/owner/Desktop/redal/venv/lib/python3.10/site-packages/rest_framework/views.py", line 469, in handle_exception
    self.raise_uncaught_exception(exc)
  File "/Users/owner/Desktop/redal/venv/lib/python3.10/site-packages/rest_framework/views.py", line 480, in raise_uncaught_exception
    raise exc
  File "/Users/owner/Desktop/redal/venv/lib/python3.10/site-packages/rest_framework/views.py", line 506, in dispatch
    response = handler(request, *args, **kwargs)
  File "/Users/owner/Desktop/redal/authentication/views.py", line 27, in post
    CustomUser.objects.create(serializer.validated_data['email'],
TypeError: CustomUserManager.create() got multiple values for argument 'password'
ERROR 2022-09-19 23:28:02,411 187 basehttp.py basehttp 35362 123145342099456 "POST /api/v1/auth/register/ HTTP/1.1" 500 92128
ERROR 2022-09-19 23:28:02,470 241 log.py log 35362 123145358888960 Internal Server Error: /api/v1/auth/register/
Traceback (most recent call last):
  File "/Users/owner/Desktop/redal/venv/lib/python3.10/site-packages/django/core/handlers/exception.py", line 55, in inner
    response = get_response(request)
  File "/Users/owner/Desktop/redal/venv/lib/python3.10/site-packages/django/core/handlers/base.py", line 197, in _get_response
    response = wrapped_callback(request, *callback_args, **callback_kwargs)
  File "/Users/owner/Desktop/redal/venv/lib/python3.10/site-packages/django/views/decorators/csrf.py", line 54, in wrapped_view
    return view_func(*args, **kwargs)
  File "/Users/owner/Desktop/redal/venv/lib/python3.10/site-packages/django/views/generic/base.py", line 103, in view
    return self.dispatch(request, *args, **kwargs)
  File "/Users/owner/Desktop/redal/venv/lib/python3.10/site-packages/rest_framework/views.py", line 509, in dispatch
    response = self.handle_exception(exc)
  File "/Users/owner/Desktop/redal/venv/lib/python3.10/site-packages/rest_framework/views.py", line 469, in handle_exception
    self.raise_uncaught_exception(exc)
  File "/Users/owner/Desktop/redal/venv/lib/python3.10/site-packages/rest_framework/views.py", line 480, in raise_uncaught_exception
    raise exc
  File "/Users/owner/Desktop/redal/venv/lib/python3.10/site-packages/rest_framework/views.py", line 506, in dispatch
    response = handler(request, *args, **kwargs)
  File "/Users/owner/Desktop/redal/authentication/views.py", line 27, in post
    CustomUser.objects.create(serializer.validated_data['email'],
TypeError: CustomUserManager.create() got multiple values for argument 'password'
ERROR 2022-09-19 23:28:02,471 187 basehttp.py basehttp 35362 123145358888960 "POST /api/v1/auth/register/ HTTP/1.1" 500 92128
ERROR 2022-09-19 23:30:28,826 241 log.py log 35412 123145413922816 Internal Server Error: /api/v1/auth/register/
Traceback (most recent call last):
  File "/Users/owner/Desktop/redal/venv/lib/python3.10/site-packages/django/core/handlers/exception.py", line 55, in inner
    response = get_response(request)
  File "/Users/owner/Desktop/redal/venv/lib/python3.10/site-packages/django/core/handlers/base.py", line 197, in _get_response
    response = wrapped_callback(request, *callback_args, **callback_kwargs)
  File "/Users/owner/Desktop/redal/venv/lib/python3.10/site-packages/django/views/decorators/csrf.py", line 54, in wrapped_view
    return view_func(*args, **kwargs)
  File "/Users/owner/Desktop/redal/venv/lib/python3.10/site-packages/django/views/generic/base.py", line 103, in view
    return self.dispatch(request, *args, **kwargs)
  File "/Users/owner/Desktop/redal/venv/lib/python3.10/site-packages/rest_framework/views.py", line 509, in dispatch
    response = self.handle_exception(exc)
  File "/Users/owner/Desktop/redal/venv/lib/python3.10/site-packages/rest_framework/views.py", line 469, in handle_exception
    self.raise_uncaught_exception(exc)
  File "/Users/owner/Desktop/redal/venv/lib/python3.10/site-packages/rest_framework/views.py", line 480, in raise_uncaught_exception
    raise exc
  File "/Users/owner/Desktop/redal/venv/lib/python3.10/site-packages/rest_framework/views.py", line 506, in dispatch
    response = handler(request, *args, **kwargs)
  File "/Users/owner/Desktop/redal/authentication/views.py", line 27, in post
    extra_fields = {key:value for key, value in serializer.validated_data if key not in exclude}
  File "/Users/owner/Desktop/redal/authentication/views.py", line 27, in <dictcomp>
    extra_fields = {key:value for key, value in serializer.validated_data if key not in exclude}
ValueError: too many values to unpack (expected 2)
ERROR 2022-09-19 23:30:28,875 187 basehttp.py basehttp 35412 123145413922816 "POST /api/v1/auth/register/ HTTP/1.1" 500 96057
ERROR 2022-09-19 23:32:50,839 241 log.py log 35466 123145339461632 Internal Server Error: /api/v1/auth/register/
Traceback (most recent call last):
  File "/Users/owner/Desktop/redal/venv/lib/python3.10/site-packages/django/core/handlers/exception.py", line 55, in inner
    response = get_response(request)
  File "/Users/owner/Desktop/redal/venv/lib/python3.10/site-packages/django/core/handlers/base.py", line 197, in _get_response
    response = wrapped_callback(request, *callback_args, **callback_kwargs)
  File "/Users/owner/Desktop/redal/venv/lib/python3.10/site-packages/django/views/decorators/csrf.py", line 54, in wrapped_view
    return view_func(*args, **kwargs)
  File "/Users/owner/Desktop/redal/venv/lib/python3.10/site-packages/django/views/generic/base.py", line 103, in view
    return self.dispatch(request, *args, **kwargs)
  File "/Users/owner/Desktop/redal/venv/lib/python3.10/site-packages/rest_framework/views.py", line 509, in dispatch
    response = self.handle_exception(exc)
  File "/Users/owner/Desktop/redal/venv/lib/python3.10/site-packages/rest_framework/views.py", line 469, in handle_exception
    self.raise_uncaught_exception(exc)
  File "/Users/owner/Desktop/redal/venv/lib/python3.10/site-packages/rest_framework/views.py", line 480, in raise_uncaught_exception
    raise exc
  File "/Users/owner/Desktop/redal/venv/lib/python3.10/site-packages/rest_framework/views.py", line 506, in dispatch
    response = handler(request, *args, **kwargs)
  File "/Users/owner/Desktop/redal/authentication/views.py", line 28, in post
    CustomUser.objects.create(serializer.validated_data['email'],
  File "/Users/owner/Desktop/redal/account/models.py", line 30, in create
    user = self.model(email=email, password=password, **extra_fields)
  File "/Users/owner/Desktop/redal/venv/lib/python3.10/site-packages/django/db/models/base.py", line 585, in __init__
    raise TypeError(
TypeError: CustomUser() got unexpected keyword arguments: 'confirm_password'
ERROR 2022-09-19 23:32:50,841 187 basehttp.py basehttp 35466 123145339461632 "POST /api/v1/auth/register/ HTTP/1.1" 500 103598
ERROR 2022-09-20 18:20:07,355 241 log.py log 43875 123145363996672 Internal Server Error: /api/v1/auth/logout/
Traceback (most recent call last):
  File "/Users/owner/Desktop/redal/venv/lib/python3.10/site-packages/django/core/handlers/exception.py", line 55, in inner
    response = get_response(request)
  File "/Users/owner/Desktop/redal/venv/lib/python3.10/site-packages/django/core/handlers/base.py", line 197, in _get_response
    response = wrapped_callback(request, *callback_args, **callback_kwargs)
  File "/Users/owner/Desktop/redal/venv/lib/python3.10/site-packages/django/views/decorators/csrf.py", line 54, in wrapped_view
    return view_func(*args, **kwargs)
  File "/Users/owner/Desktop/redal/venv/lib/python3.10/site-packages/django/views/generic/base.py", line 103, in view
    return self.dispatch(request, *args, **kwargs)
  File "/Users/owner/Desktop/redal/venv/lib/python3.10/site-packages/rest_framework/views.py", line 509, in dispatch
    response = self.handle_exception(exc)
  File "/Users/owner/Desktop/redal/venv/lib/python3.10/site-packages/rest_framework/views.py", line 469, in handle_exception
    self.raise_uncaught_exception(exc)
  File "/Users/owner/Desktop/redal/venv/lib/python3.10/site-packages/rest_framework/views.py", line 480, in raise_uncaught_exception
    raise exc
  File "/Users/owner/Desktop/redal/venv/lib/python3.10/site-packages/rest_framework/views.py", line 506, in dispatch
    response = handler(request, *args, **kwargs)
  File "/Users/owner/Desktop/redal/authentication/views.py", line 26, in post
    CustomUser.objects.logout(
  File "/Users/owner/Desktop/redal/account/models.py", line 30, in logout
    token = RefreshToken(refresh_token)
  File "/Users/owner/Desktop/redal/venv/lib/python3.10/site-packages/rest_framework_simplejwt/tokens.py", line 47, in __init__
    self.verify()
  File "/Users/owner/Desktop/redal/venv/lib/python3.10/site-packages/rest_framework_simplejwt/tokens.py", line 218, in verify
    self.check_blacklist()
  File "/Users/owner/Desktop/redal/venv/lib/python3.10/site-packages/rest_framework_simplejwt/tokens.py", line 230, in check_blacklist
    raise TokenError(_("Token is blacklisted"))
rest_framework_simplejwt.exceptions.TokenError: Token is blacklisted
ERROR 2022-09-20 18:20:07,418 187 basehttp.py basehttp 43875 123145363996672 "POST /api/v1/auth/logout/ HTTP/1.1" 500 108391
ERROR 2022-09-20 18:20:09,305 241 log.py log 43875 123145363996672 Internal Server Error: /api/v1/auth/logout/
Traceback (most recent call last):
  File "/Users/owner/Desktop/redal/venv/lib/python3.10/site-packages/django/core/handlers/exception.py", line 55, in inner
    response = get_response(request)
  File "/Users/owner/Desktop/redal/venv/lib/python3.10/site-packages/django/core/handlers/base.py", line 197, in _get_response
    response = wrapped_callback(request, *callback_args, **callback_kwargs)
  File "/Users/owner/Desktop/redal/venv/lib/python3.10/site-packages/django/views/decorators/csrf.py", line 54, in wrapped_view
    return view_func(*args, **kwargs)
  File "/Users/owner/Desktop/redal/venv/lib/python3.10/site-packages/django/views/generic/base.py", line 103, in view
    return self.dispatch(request, *args, **kwargs)
  File "/Users/owner/Desktop/redal/venv/lib/python3.10/site-packages/rest_framework/views.py", line 509, in dispatch
    response = self.handle_exception(exc)
  File "/Users/owner/Desktop/redal/venv/lib/python3.10/site-packages/rest_framework/views.py", line 469, in handle_exception
    self.raise_uncaught_exception(exc)
  File "/Users/owner/Desktop/redal/venv/lib/python3.10/site-packages/rest_framework/views.py", line 480, in raise_uncaught_exception
    raise exc
  File "/Users/owner/Desktop/redal/venv/lib/python3.10/site-packages/rest_framework/views.py", line 506, in dispatch
    response = handler(request, *args, **kwargs)
  File "/Users/owner/Desktop/redal/authentication/views.py", line 26, in post
    CustomUser.objects.logout(
  File "/Users/owner/Desktop/redal/account/models.py", line 30, in logout
    token = RefreshToken(refresh_token)
  File "/Users/owner/Desktop/redal/venv/lib/python3.10/site-packages/rest_framework_simplejwt/tokens.py", line 47, in __init__
    self.verify()
  File "/Users/owner/Desktop/redal/venv/lib/python3.10/site-packages/rest_framework_simplejwt/tokens.py", line 218, in verify
    self.check_blacklist()
  File "/Users/owner/Desktop/redal/venv/lib/python3.10/site-packages/rest_framework_simplejwt/tokens.py", line 230, in check_blacklist
    raise TokenError(_("Token is blacklisted"))
rest_framework_simplejwt.exceptions.TokenError: Token is blacklisted
ERROR 2022-09-20 18:20:09,307 187 basehttp.py basehttp 43875 123145363996672 "POST /api/v1/auth/logout/ HTTP/1.1" 500 108391
ERROR 2022-09-20 18:20:09,798 241 log.py log 43875 123145363996672 Internal Server Error: /api/v1/auth/logout/
Traceback (most recent call last):
  File "/Users/owner/Desktop/redal/venv/lib/python3.10/site-packages/django/core/handlers/exception.py", line 55, in inner
    response = get_response(request)
  File "/Users/owner/Desktop/redal/venv/lib/python3.10/site-packages/django/core/handlers/base.py", line 197, in _get_response
    response = wrapped_callback(request, *callback_args, **callback_kwargs)
  File "/Users/owner/Desktop/redal/venv/lib/python3.10/site-packages/django/views/decorators/csrf.py", line 54, in wrapped_view
    return view_func(*args, **kwargs)
  File "/Users/owner/Desktop/redal/venv/lib/python3.10/site-packages/django/views/generic/base.py", line 103, in view
    return self.dispatch(request, *args, **kwargs)
  File "/Users/owner/Desktop/redal/venv/lib/python3.10/site-packages/rest_framework/views.py", line 509, in dispatch
    response = self.handle_exception(exc)
  File "/Users/owner/Desktop/redal/venv/lib/python3.10/site-packages/rest_framework/views.py", line 469, in handle_exception
    self.raise_uncaught_exception(exc)
  File "/Users/owner/Desktop/redal/venv/lib/python3.10/site-packages/rest_framework/views.py", line 480, in raise_uncaught_exception
    raise exc
  File "/Users/owner/Desktop/redal/venv/lib/python3.10/site-packages/rest_framework/views.py", line 506, in dispatch
    response = handler(request, *args, **kwargs)
  File "/Users/owner/Desktop/redal/authentication/views.py", line 26, in post
    CustomUser.objects.logout(
  File "/Users/owner/Desktop/redal/account/models.py", line 30, in logout
    token = RefreshToken(refresh_token)
  File "/Users/owner/Desktop/redal/venv/lib/python3.10/site-packages/rest_framework_simplejwt/tokens.py", line 47, in __init__
    self.verify()
  File "/Users/owner/Desktop/redal/venv/lib/python3.10/site-packages/rest_framework_simplejwt/tokens.py", line 218, in verify
    self.check_blacklist()
  File "/Users/owner/Desktop/redal/venv/lib/python3.10/site-packages/rest_framework_simplejwt/tokens.py", line 230, in check_blacklist
    raise TokenError(_("Token is blacklisted"))
rest_framework_simplejwt.exceptions.TokenError: Token is blacklisted
ERROR 2022-09-20 18:20:09,799 187 basehttp.py basehttp 43875 123145363996672 "POST /api/v1/auth/logout/ HTTP/1.1" 500 108391
ERROR 2022-09-20 18:20:10,331 241 log.py log 43875 123145363996672 Internal Server Error: /api/v1/auth/logout/
Traceback (most recent call last):
  File "/Users/owner/Desktop/redal/venv/lib/python3.10/site-packages/django/core/handlers/exception.py", line 55, in inner
    response = get_response(request)
  File "/Users/owner/Desktop/redal/venv/lib/python3.10/site-packages/django/core/handlers/base.py", line 197, in _get_response
    response = wrapped_callback(request, *callback_args, **callback_kwargs)
  File "/Users/owner/Desktop/redal/venv/lib/python3.10/site-packages/django/views/decorators/csrf.py", line 54, in wrapped_view
    return view_func(*args, **kwargs)
  File "/Users/owner/Desktop/redal/venv/lib/python3.10/site-packages/django/views/generic/base.py", line 103, in view
    return self.dispatch(request, *args, **kwargs)
  File "/Users/owner/Desktop/redal/venv/lib/python3.10/site-packages/rest_framework/views.py", line 509, in dispatch
    response = self.handle_exception(exc)
  File "/Users/owner/Desktop/redal/venv/lib/python3.10/site-packages/rest_framework/views.py", line 469, in handle_exception
    self.raise_uncaught_exception(exc)
  File "/Users/owner/Desktop/redal/venv/lib/python3.10/site-packages/rest_framework/views.py", line 480, in raise_uncaught_exception
    raise exc
  File "/Users/owner/Desktop/redal/venv/lib/python3.10/site-packages/rest_framework/views.py", line 506, in dispatch
    response = handler(request, *args, **kwargs)
  File "/Users/owner/Desktop/redal/authentication/views.py", line 26, in post
    CustomUser.objects.logout(
  File "/Users/owner/Desktop/redal/account/models.py", line 30, in logout
    token = RefreshToken(refresh_token)
  File "/Users/owner/Desktop/redal/venv/lib/python3.10/site-packages/rest_framework_simplejwt/tokens.py", line 47, in __init__
    self.verify()
  File "/Users/owner/Desktop/redal/venv/lib/python3.10/site-packages/rest_framework_simplejwt/tokens.py", line 218, in verify
    self.check_blacklist()
  File "/Users/owner/Desktop/redal/venv/lib/python3.10/site-packages/rest_framework_simplejwt/tokens.py", line 230, in check_blacklist
    raise TokenError(_("Token is blacklisted"))
rest_framework_simplejwt.exceptions.TokenError: Token is blacklisted
ERROR 2022-09-20 18:20:10,334 187 basehttp.py basehttp 43875 123145363996672 "POST /api/v1/auth/logout/ HTTP/1.1" 500 108391
ERROR 2022-09-20 18:20:10,464 241 log.py log 43875 123145363996672 Internal Server Error: /api/v1/auth/logout/
Traceback (most recent call last):
  File "/Users/owner/Desktop/redal/venv/lib/python3.10/site-packages/django/core/handlers/exception.py", line 55, in inner
    response = get_response(request)
  File "/Users/owner/Desktop/redal/venv/lib/python3.10/site-packages/django/core/handlers/base.py", line 197, in _get_response
    response = wrapped_callback(request, *callback_args, **callback_kwargs)
  File "/Users/owner/Desktop/redal/venv/lib/python3.10/site-packages/django/views/decorators/csrf.py", line 54, in wrapped_view
    return view_func(*args, **kwargs)
  File "/Users/owner/Desktop/redal/venv/lib/python3.10/site-packages/django/views/generic/base.py", line 103, in view
    return self.dispatch(request, *args, **kwargs)
  File "/Users/owner/Desktop/redal/venv/lib/python3.10/site-packages/rest_framework/views.py", line 509, in dispatch
    response = self.handle_exception(exc)
  File "/Users/owner/Desktop/redal/venv/lib/python3.10/site-packages/rest_framework/views.py", line 469, in handle_exception
    self.raise_uncaught_exception(exc)
  File "/Users/owner/Desktop/redal/venv/lib/python3.10/site-packages/rest_framework/views.py", line 480, in raise_uncaught_exception
    raise exc
  File "/Users/owner/Desktop/redal/venv/lib/python3.10/site-packages/rest_framework/views.py", line 506, in dispatch
    response = handler(request, *args, **kwargs)
  File "/Users/owner/Desktop/redal/authentication/views.py", line 26, in post
    CustomUser.objects.logout(
  File "/Users/owner/Desktop/redal/account/models.py", line 30, in logout
    token = RefreshToken(refresh_token)
  File "/Users/owner/Desktop/redal/venv/lib/python3.10/site-packages/rest_framework_simplejwt/tokens.py", line 47, in __init__
    self.verify()
  File "/Users/owner/Desktop/redal/venv/lib/python3.10/site-packages/rest_framework_simplejwt/tokens.py", line 218, in verify
    self.check_blacklist()
  File "/Users/owner/Desktop/redal/venv/lib/python3.10/site-packages/rest_framework_simplejwt/tokens.py", line 230, in check_blacklist
    raise TokenError(_("Token is blacklisted"))
rest_framework_simplejwt.exceptions.TokenError: Token is blacklisted
ERROR 2022-09-20 18:20:10,465 187 basehttp.py basehttp 43875 123145363996672 "POST /api/v1/auth/logout/ HTTP/1.1" 500 108391
ERROR 2022-09-20 18:20:10,651 241 log.py log 43875 123145363996672 Internal Server Error: /api/v1/auth/logout/
Traceback (most recent call last):
  File "/Users/owner/Desktop/redal/venv/lib/python3.10/site-packages/django/core/handlers/exception.py", line 55, in inner
    response = get_response(request)
  File "/Users/owner/Desktop/redal/venv/lib/python3.10/site-packages/django/core/handlers/base.py", line 197, in _get_response
    response = wrapped_callback(request, *callback_args, **callback_kwargs)
  File "/Users/owner/Desktop/redal/venv/lib/python3.10/site-packages/django/views/decorators/csrf.py", line 54, in wrapped_view
    return view_func(*args, **kwargs)
  File "/Users/owner/Desktop/redal/venv/lib/python3.10/site-packages/django/views/generic/base.py", line 103, in view
    return self.dispatch(request, *args, **kwargs)
  File "/Users/owner/Desktop/redal/venv/lib/python3.10/site-packages/rest_framework/views.py", line 509, in dispatch
    response = self.handle_exception(exc)
  File "/Users/owner/Desktop/redal/venv/lib/python3.10/site-packages/rest_framework/views.py", line 469, in handle_exception
    self.raise_uncaught_exception(exc)
  File "/Users/owner/Desktop/redal/venv/lib/python3.10/site-packages/rest_framework/views.py", line 480, in raise_uncaught_exception
    raise exc
  File "/Users/owner/Desktop/redal/venv/lib/python3.10/site-packages/rest_framework/views.py", line 506, in dispatch
    response = handler(request, *args, **kwargs)
  File "/Users/owner/Desktop/redal/authentication/views.py", line 26, in post
    CustomUser.objects.logout(
  File "/Users/owner/Desktop/redal/account/models.py", line 30, in logout
    token = RefreshToken(refresh_token)
  File "/Users/owner/Desktop/redal/venv/lib/python3.10/site-packages/rest_framework_simplejwt/tokens.py", line 47, in __init__
    self.verify()
  File "/Users/owner/Desktop/redal/venv/lib/python3.10/site-packages/rest_framework_simplejwt/tokens.py", line 218, in verify
    self.check_blacklist()
  File "/Users/owner/Desktop/redal/venv/lib/python3.10/site-packages/rest_framework_simplejwt/tokens.py", line 230, in check_blacklist
    raise TokenError(_("Token is blacklisted"))
rest_framework_simplejwt.exceptions.TokenError: Token is blacklisted
ERROR 2022-09-20 18:20:10,652 187 basehttp.py basehttp 43875 123145363996672 "POST /api/v1/auth/logout/ HTTP/1.1" 500 108391
ERROR 2022-09-20 18:20:10,851 241 log.py log 43875 123145363996672 Internal Server Error: /api/v1/auth/logout/
Traceback (most recent call last):
  File "/Users/owner/Desktop/redal/venv/lib/python3.10/site-packages/django/core/handlers/exception.py", line 55, in inner
    response = get_response(request)
  File "/Users/owner/Desktop/redal/venv/lib/python3.10/site-packages/django/core/handlers/base.py", line 197, in _get_response
    response = wrapped_callback(request, *callback_args, **callback_kwargs)
  File "/Users/owner/Desktop/redal/venv/lib/python3.10/site-packages/django/views/decorators/csrf.py", line 54, in wrapped_view
    return view_func(*args, **kwargs)
  File "/Users/owner/Desktop/redal/venv/lib/python3.10/site-packages/django/views/generic/base.py", line 103, in view
    return self.dispatch(request, *args, **kwargs)
  File "/Users/owner/Desktop/redal/venv/lib/python3.10/site-packages/rest_framework/views.py", line 509, in dispatch
    response = self.handle_exception(exc)
  File "/Users/owner/Desktop/redal/venv/lib/python3.10/site-packages/rest_framework/views.py", line 469, in handle_exception
    self.raise_uncaught_exception(exc)
  File "/Users/owner/Desktop/redal/venv/lib/python3.10/site-packages/rest_framework/views.py", line 480, in raise_uncaught_exception
    raise exc
  File "/Users/owner/Desktop/redal/venv/lib/python3.10/site-packages/rest_framework/views.py", line 506, in dispatch
    response = handler(request, *args, **kwargs)
  File "/Users/owner/Desktop/redal/authentication/views.py", line 26, in post
    CustomUser.objects.logout(
  File "/Users/owner/Desktop/redal/account/models.py", line 30, in logout
    token = RefreshToken(refresh_token)
  File "/Users/owner/Desktop/redal/venv/lib/python3.10/site-packages/rest_framework_simplejwt/tokens.py", line 47, in __init__
    self.verify()
  File "/Users/owner/Desktop/redal/venv/lib/python3.10/site-packages/rest_framework_simplejwt/tokens.py", line 218, in verify
    self.check_blacklist()
  File "/Users/owner/Desktop/redal/venv/lib/python3.10/site-packages/rest_framework_simplejwt/tokens.py", line 230, in check_blacklist
    raise TokenError(_("Token is blacklisted"))
rest_framework_simplejwt.exceptions.TokenError: Token is blacklisted
ERROR 2022-09-20 18:20:10,852 187 basehttp.py basehttp 43875 123145363996672 "POST /api/v1/auth/logout/ HTTP/1.1" 500 108391
